

```
(base) D:\github\django-tally>pipenv shell
Loading .env environment variables…
Launching subshell in virtual environment…
Microsoft Windows [Version 10.0.17763.973]
(c) 2018 Microsoft Corporation. All rights reserved.

(django-tally-QTYVOJb0) (base) D:\github\django-tally>celery -A proj worker -l info
Traceback (most recent call last):
  File "c:\users\guido\miniconda3\Lib\runpy.py", line 193, in _run_module_as_main
    "__main__", mod_spec)
  File "c:\users\guido\miniconda3\Lib\runpy.py", line 85, in _run_code
    exec(code, run_globals)
  File "C:\Users\guido\.virtualenvs\django-tally-QTYVOJb0\Scripts\celery.exe\__main__.py", line 7, in <module>
  File "c:\users\guido\.virtualenvs\django-tally-qtyvojb0\lib\site-packages\celery\__main__.py", line 30, in main
    main()
  File "c:\users\guido\.virtualenvs\django-tally-qtyvojb0\lib\site-packages\celery\bin\celery.py", line 81, in main
    cmd.execute_from_commandline(argv)
  File "c:\users\guido\.virtualenvs\django-tally-qtyvojb0\lib\site-packages\celery\bin\celery.py", line 793, in execute_from_commandline
    super(CeleryCommand, self).execute_from_commandline(argv)))
  File "c:\users\guido\.virtualenvs\django-tally-qtyvojb0\lib\site-packages\celery\bin\base.py", line 309, in execute_from_commandline
    argv = self.setup_app_from_commandline(argv)
  File "c:\users\guido\.virtualenvs\django-tally-qtyvojb0\lib\site-packages\celery\bin\base.py", line 469, in setup_app_from_commandline
    self.app = self.find_app(app)
  File "c:\users\guido\.virtualenvs\django-tally-qtyvojb0\lib\site-packages\celery\bin\base.py", line 489, in find_app
    return find_app(app, symbol_by_name=self.symbol_by_name)
  File "c:\users\guido\.virtualenvs\django-tally-qtyvojb0\lib\site-packages\celery\app\utils.py", line 235, in find_app
    sym = symbol_by_name(app, imp=imp)
  File "c:\users\guido\.virtualenvs\django-tally-qtyvojb0\lib\site-packages\celery\bin\base.py", line 492, in symbol_by_name
    return symbol_by_name(name, imp=imp)
  File "c:\users\guido\.virtualenvs\django-tally-qtyvojb0\lib\site-packages\kombu\utils\__init__.py", line 96, in symbol_by_name
    module = imp(module_name, package=package, **kwargs)
  File "c:\users\guido\.virtualenvs\django-tally-qtyvojb0\lib\site-packages\celery\utils\imports.py", line 101, in import_from_cwd
    return imp(module, package=package)
  File "c:\users\guido\.virtualenvs\django-tally-qtyvojb0\lib\importlib\__init__.py", line 127, in import_module
    return _bootstrap._gcd_import(name[level:], package, level)
  File "<frozen importlib._bootstrap>", line 1006, in _gcd_import
  File "<frozen importlib._bootstrap>", line 983, in _find_and_load
  File "<frozen importlib._bootstrap>", line 965, in _find_and_load_unlocked
ModuleNotFoundError: No module named 'proj'

(django-tally-QTYVOJb0) (base) D:\github\django-tally>celery -A tally worker -l info
Traceback (most recent call last):
  File "c:\users\guido\miniconda3\Lib\runpy.py", line 193, in _run_module_as_main
    "__main__", mod_spec)
  File "c:\users\guido\miniconda3\Lib\runpy.py", line 85, in _run_code
    exec(code, run_globals)
  File "C:\Users\guido\.virtualenvs\django-tally-QTYVOJb0\Scripts\celery.exe\__main__.py", line 7, in <module>
  File "c:\users\guido\.virtualenvs\django-tally-qtyvojb0\lib\site-packages\celery\__main__.py", line 30, in main
    main()
  File "c:\users\guido\.virtualenvs\django-tally-qtyvojb0\lib\site-packages\celery\bin\celery.py", line 81, in main
    cmd.execute_from_commandline(argv)
  File "c:\users\guido\.virtualenvs\django-tally-qtyvojb0\lib\site-packages\celery\bin\celery.py", line 793, in execute_from_commandline
    super(CeleryCommand, self).execute_from_commandline(argv)))
  File "c:\users\guido\.virtualenvs\django-tally-qtyvojb0\lib\site-packages\celery\bin\base.py", line 311, in execute_from_commandline
    return self.handle_argv(self.prog_name, argv[1:])
  File "c:\users\guido\.virtualenvs\django-tally-qtyvojb0\lib\site-packages\celery\bin\celery.py", line 785, in handle_argv
    return self.execute(command, argv)
  File "c:\users\guido\.virtualenvs\django-tally-qtyvojb0\lib\site-packages\celery\bin\celery.py", line 717, in execute
    ).run_from_argv(self.prog_name, argv[1:], command=argv[0])
  File "c:\users\guido\.virtualenvs\django-tally-qtyvojb0\lib\site-packages\celery\bin\worker.py", line 179, in run_from_argv
    return self(*args, **options)
  File "c:\users\guido\.virtualenvs\django-tally-qtyvojb0\lib\site-packages\celery\bin\base.py", line 274, in __call__
    ret = self.run(*args, **kwargs)
  File "c:\users\guido\.virtualenvs\django-tally-qtyvojb0\lib\site-packages\celery\bin\worker.py", line 194, in run
    pool_cls = (concurrency.get_implementation(pool_cls) or
  File "c:\users\guido\.virtualenvs\django-tally-qtyvojb0\lib\site-packages\celery\concurrency\__init__.py", line 29, in get_implementation
    return symbol_by_name(cls, ALIASES)
  File "c:\users\guido\.virtualenvs\django-tally-qtyvojb0\lib\site-packages\kombu\utils\__init__.py", line 96, in symbol_by_name
    module = imp(module_name, package=package, **kwargs)
  File "c:\users\guido\.virtualenvs\django-tally-qtyvojb0\lib\importlib\__init__.py", line 127, in import_module
    return _bootstrap._gcd_import(name[level:], package, level)
  File "<frozen importlib._bootstrap>", line 1006, in _gcd_import
  File "<frozen importlib._bootstrap>", line 983, in _find_and_load
  File "<frozen importlib._bootstrap>", line 967, in _find_and_load_unlocked
  File "<frozen importlib._bootstrap>", line 677, in _load_unlocked
  File "<frozen importlib._bootstrap_external>", line 728, in exec_module
  File "<frozen importlib._bootstrap>", line 219, in _call_with_frames_removed
  File "c:\users\guido\.virtualenvs\django-tally-qtyvojb0\lib\site-packages\celery\concurrency\prefork.py", line 20, in <module>
    from celery.concurrency.base import BasePool
  File "c:\users\guido\.virtualenvs\django-tally-qtyvojb0\lib\site-packages\celery\concurrency\base.py", line 21, in <module>
    from celery.utils import timer2
  File "c:\users\guido\.virtualenvs\django-tally-qtyvojb0\lib\site-packages\celery\utils\timer2.py", line 19
    from kombu.async.timer import Entry, Timer as Schedule, to_timestamp, logger
                   ^
SyntaxError: invalid syntax
```

https://stackoverflow.com/questions/53466160/unable-to-start-celery-worker-instance-syntax-error   
Well, its a known issue for Celery. Celery does not support python 3.7 yet. Same goes to Kombu. So downgrade python to 3.6 or former. You can check the status of that issue at https://github.com/celery/celery/issues/4500   
edited Nov 25 '18 at 10:40

【Issue Solved】  
```
$ conda create -n python3.6 python=3.6
$ pip install pipenv
$ cd /path/to/django-tally
$ conda activate python3.6
$ pipenv --rm
$ pipenv install
$ celery -A tally worker -l info
```

【Logs】
```
(base) D:\tmp\miniconda>conda create -n python3.6 python=3.6
Collecting package metadata (current_repodata.json): done
Solving environment: done


==> WARNING: A newer version of conda exists. <==
  current version: 4.7.12
  latest version: 4.8.1

Please update conda by running

    $ conda update -n base -c defaults conda



## Package Plan ##

  environment location: C:\Users\guido\Miniconda3\envs\python3.6

  added / updated specs:
    - python=3.6


The following NEW packages will be INSTALLED:

  certifi            pkgs/main/win-64::certifi-2019.11.28-py36_0
  pip                pkgs/main/win-64::pip-19.3.1-py36_0
  python             pkgs/main/win-64::python-3.6.10-h9f7ef89_0
  setuptools         pkgs/main/win-64::setuptools-44.0.0-py36_0
  sqlite             pkgs/main/win-64::sqlite-3.30.1-he774522_0
  vc                 pkgs/main/win-64::vc-14.1-h0510ff6_4
  vs2015_runtime     pkgs/main/win-64::vs2015_runtime-14.16.27012-hf0eaf9b_1
  wheel              pkgs/main/win-64::wheel-0.33.6-py36_0
  wincertstore       pkgs/main/win-64::wincertstore-0.2-py36h7fe50ca_0


Proceed ([y]/n)? y

Preparing transaction: done
Verifying transaction: done
Executing transaction: done
#
# To activate this environment, use
#
#     $ conda activate python3.6
#
# To deactivate an active environment, use
#
#     $ conda deactivate
```

```
(base) PS D:\> cd github/django-tally
(base) PS D:\github\django-tally> pipenv shell
Loading .env environment variables…
Warning: Your Pipfile requires python_version 3.6, but you are using 3.7.4 (C:\Users\guido\.\d\S\python.exe).
  $ pipenv --rm and rebuilding the virtual environment may resolve the issue.
  $ pipenv check will surely fail.
Launching subshell in virtual environment…
Windows PowerShell
Copyright (C) Microsoft Corporation. All rights reserved.

PS D:\github\django-tally> pipenv --rm
Removing virtualenv (C:\Users\guido\.virtualenvs\django-tally-QTYVOJb0)…
PS D:\github\django-tally> pipenv shell
Shell for C:\Users\guido\.virtualenvs\django-tally-QTYVOJb0 already activated.
No action taken to avoid nested environments.
PS D:\github\django-tally> pipenv install
Warning: Python 3.6 was not found on your system…
You can specify specific versions of Python with:
  $ pipenv --python path\to\python
PS D:\github\django-tally> exit
(base) PS D:\github\django-tally> conda activate python3.6
(python3.6) PS D:\github\django-tally> pipenv install
Creating a virtualenv for this project…
Pipfile: D:\github\django-tally\Pipfile
Using C:/Users/guido/Miniconda3/envs/python3.6/python.exe (3.6.10) to create virtualenv…
[==  ] Creating virtual environment...Already using interpreter C:\Users\guido\Miniconda3\envs\python3.6\python.exe
Using base prefix 'C:\\Users\\guido\\Miniconda3\\envs\\python3.6'
  No LICENSE.txt / LICENSE found in source
New python executable in C:\Users\guido\.virtualenvs\django-tally-QTYVOJb0\Scripts\python.exe
Installing setuptools, pip, wheel...
done.
Running virtualenv with interpreter C:/Users/guido/Miniconda3/envs/python3.6/python.exe

Successfully created virtual environment!
Virtualenv location: C:\Users\guido\.virtualenvs\django-tally-QTYVOJb0
Pipfile.lock (dd259d) out of date, updating to (44cce1)…
Locking [dev-packages] dependencies…
Locking [packages] dependencies…
Success!
Updated Pipfile.lock (dd259d)!
Installing dependencies from Pipfile.lock (dd259d)…
An error occurred while installing importlib-metadata==1.4.0 ; python_version < '3.8' --hash=sha256:bdd9b7c397c273bcc9a11d6629a38487cd07154fa255a467bf704cd2c258e359 --hash=sha256:f17c015735e1a88296994c0697ecea7e11db24290941983b08c9feb30921e6d8! Will try again.
An error occurred while installing mock==3.0.5 --hash=sha256:83657d894c90d5681d62155c82bda9c1187827525880eda8ff5df4ec813437c3 --hash=sha256:d157e52d4e5b938c550f39eb2fd15610db062441a9c2747d3dbfa9298211d0f8! Will try again.
An error occurred while installing pandas==0.25.3 --hash=sha256:00dff3a8e337f5ed7ad295d98a31821d3d0fe7792da82d78d7fd79b89c03ea9d --hash=sha256:22361b1597c8c2ffd697aa9bf85423afa9e1fcfa6b1ea821054a244d5f24d75e --hash=sha256:255920e63850dc512ce356233081098554d641ba99c3767dde9e9f35630f994b --hash=sha256:26382aab9c119735908d94d2c5c08020a4a0a82969b7e5eefb92f902b3b30ad7 --hash=sha256:33970f4cacdd9a0ddb8f21e151bfb9f178afb7c36eb7c25b9094c02876f385c2 --hash=sha256:4545467a637e0e1393f7d05d61dace89689ad6d6f66f267f86fff737b702cce9 --hash=sha256:52da74df8a9c9a103af0a72c9d5fdc8e0183a90884278db7f386b5692a2220a4 --hash=sha256:61741f5aeb252f39c3031d11405305b6d10ce663c53bc3112705d7ad66c013d0 --hash=sha256:6a3ac2c87e4e32a969921d1428525f09462770c349147aa8e9ab95f88c71ec71 --hash=sha256:7458c48e3d15b8aaa7d575be60e1e4dd70348efcd9376656b72fecd55c59a4c3 --hash=sha256:78bf638993219311377ce9836b3dc05f627a666d0dbc8cec37c0ff3c9ada673b --hash=sha256:8153705d6545fd9eb6dd2bc79301bff08825d2e2f716d5dced48daafc2d0b81f --hash=sha256:975c461accd14e89d71772e89108a050fa824c0b87a67d34cedf245f6681fc17 --hash=sha256:9962957a27bfb70ab64103d0a7b42fa59c642fb4ed4cb75d0227b7bb9228535d --hash=sha256:adc3d3a3f9e59a38d923e90e20c4922fc62d1e5a03d083440468c6d8f3f1ae0a --hash=sha256:bbe3eb765a0b1e578833d243e2814b60c825b7fdbf4cdfe8e8aae8a08ed56ecf --hash=sha256:df8864824b1fe488cf778c3650ee59c3a0d8f42e53707de167ba6b4f7d35f133 --hash=sha256:e45055c30a608076e31a9fcd780a956ed3b1fa20db61561b8d88b79259f526f7 --hash=sha256:ee50c2142cdcf41995655d499a157d0a812fce55c97d9aad13bc1eef837ed36c! Will try again.
An error occurred while installing patsy==0.5.1 --hash=sha256:5465be1c0e670c3a965355ec09e9a502bf2c4cbe4875e8528b0221190a8a5d40 --hash=sha256:f115cec4201e1465cd58b9866b0b0e7b941caafec129869057405bfe5b5e3991! Will try again.
An error occurred while installing pylint==2.4.4 --hash=sha256:3db5468ad013380e987410a8d6956226963aed94ecb5f9d3a28acca6d9ac36cd --hash=sha256:886e6afc935ea2590b462664b161ca9a5e40168ea99e5300935f6591ad467df4! Will try again.
An error occurred while installing pytextrank==2.0.0 --hash=sha256:094a6389c0ec8c4821af2bf33e53039362e209fa8a393d4031a906dadafa88c0 --hash=sha256:1d47067f037d1f7e146f70c877d793aacc0d16747ede89e8e254df42437dd9cb! Will try again.
An error occurred while installing python-dateutil==2.8.1 --hash=sha256:73ebfe9dbf22e832286dafa60473e4cd239f8592f699aa5adaf10050e6e1823c --hash=sha256:75bb3f31ea686f1197762692a9ee6a7550b59fc6ca3a1f4b5d7e32fb98e2da2a! Will try again.
An error occurred while installing s3transfer==0.3.0 --hash=sha256:2157640a47c8b8fa2071bdd7b0d57378ec8957eede3bd083949c2dcc4d9b0dd4 --hash=sha256:e3343ae0f371781c17590cf06cb818a54484fbac9a65a5be7603a39b0a6d7b31! Will try again.
An error occurred while installing scattertext==0.0.2.56 --hash=sha256:4265dd543e8bacd3e751ecb029fb5c71bf2040ac61feb02157b3995ee7c78a92 --hash=sha256:6460284836be16c58b9678a6a9b664ae71c03c69040d170dbfda134647833051 --hash=sha256:cb7f2516e3dd07037b7a991b49cdf3c0224f4465f4ab255f17df524c36aab27c! Will try again.
An error occurred while installing scikit-learn==0.22.1 --hash=sha256:06c9816249b9664ef1b04ad6a5d4dfe0c4017c584858c4e658861c2ac5eb4f31 --hash=sha256:12ec6b2821a0b4d1b7cbe0e5d6387e64e25e6ec8cfef058b276a14509c3a537b --hash=sha256:13b9ac18d48c051dfea32783067f2e45552e45852b88f3bccdb5c72fa56df3fe --hash=sha256:1e0cb60dae75da9e72d38569d18bbad5008777defd23585035a1314a01af966c --hash=sha256:28033cb7b50b8a6c3762cddd41dc7e5449347dedfa353409a576082e76309d09 --hash=sha256:2d35ece66767dd197d020940b1dab3be92ddbb1c96aaef0936d9c4369d544d69 --hash=sha256:51ee25330fc244107588545c70e2f3570cfc4017cff09eed69d6e1d82a212b7d --hash=sha256:571476fbb826c87ad300a5aad0238c14a590ab7df5cb823ee19ac077bf13b5f4 --hash=sha256:5e0b5bebfd8bd8ab89b58c44acb95ddcc9439b23c875ed597842991cafc18b62 --hash=sha256:671874343a0b33bc0dbcae4af0b9a77c55b8132b33887fbfe086681c3f010840 --hash=sha256:6fad30299ef3dd103871ad1235b445fd5d2df47c424746eaf3c50fbc99c49cef --hash=sha256:7f1cdfd3c5e9d0951e273f49bb25bd9886537ab77e2273502b8676c3105828ae --hash=sha256:80eec2f54cc7f51c5abb743f09506e009ba2b95bf6fb0e554aa0d8959b680003 --hash=sha256:93001af23b0f1e68d93447f9d56bad631d4fc28eafd78b09469fb55aeff715b1 --hash=sha256:956a68772df02342af129e8bbe858b3053745c36beb6351a13641e3b56e0df23 --hash=sha256:96e1365ba285903e493b1e9505b533171c852f7069d038dcc3395ece952fdc78 --hash=sha256:bacc63185520d9eb295d79fa62c388fd7145783920a1fb113451a0b294994cad --hash=sha256:d92b81615854504c27063e0970aed37e644eea5991444558c8aca8fadc1483b3 --hash=sha256:d92ed650c32db013f66bba63af4922bd7a9b8c5802d4ee292332e504e567bd4a --hash=sha256:ebdf03b6e7f784e360ab26cf400cd2125d650c0903ef11086c0a3f2b4b07e603 --hash=sha256:f18ae2abc09cb94a171840829a8132dda7267c941eb431387a6014f943946825! Will try again.
An error occurred while installing statsmodels==0.10.2 --hash=sha256:172d947a1a8542eefe7155f73ead951f6748782846e8e97e73b8ebf6483d5820 --hash=sha256:1d61edd4b73f1f4ef983007cd0d797e6cafd9e7de0125584761d93f79675cdd2 --hash=sha256:3b22ed234b80cd9d38988fba487da89cae484a4c2b9088b3e7783c0a937a4568 --hash=sha256:4d1c4b4ecdff539c7fea788f919ed25f25fdc50189a5c0b1a1a966bf04f3a2b8 --hash=sha256:65f08024ef9a0bd40b63c455d02da34394658c53c16e3494dd6171e86e639f9b --hash=sha256:6cb8395c820eda886721ec2e0db41ffebb2c5a090b27ef9bf51f64e9ab1486af --hash=sha256:75d8e36693d3e7459df9d4e5e4761b0277dd1c9d028a60ef6876e8299f8b9cd7 --hash=sha256:7db46146a5e773c9905d914735fabc1e7b3b1027adc98e42060ad8e61460e647 --hash=sha256:81c1a0a9dcc46713f47a5b69b1e7d74041ed85f774009302deedad11786beee0 --hash=sha256:8954e9f1659e99a6684167432d36e25bf4e739bb3ae99709a021490f11992fed --hash=sha256:938dcf95b37fdd6404e0c1f2035b51de0cfd63a63faa9048751176ea55cb4ce9 --hash=sha256:9c9de647fa3ed058635e6a1b1bb2d3d2396f103cb1dcd00d5e70c36d8137639d --hash=sha256:9cd2194c6642a8754e85f9a6e6912cdf996bebf6ff715d3cc67f65dadfd37cc9 --hash=sha256:a7e6d67d986ef9776b80d30fba4dca1db534986ee2023bab121d70bd78d06c49 --hash=sha256:a8848b368838a62d06c9f0995bdc6f5e82e09f55440bd85c2c13c58777813ebc --hash=sha256:adb5e524be26842c867f7dfdd74d7cfb2078fe2a6159b948e2f7ccf0e3d92002 --hash=sha256:be0436f7ea14c277f30e3175dd463d2a26226d8fd360d06bb1c7cd1d9bbedafc --hash=sha256:c84625b8746ee7e613752334bfb9ff60dffb91d22f19b7f08b8c387776dc42c1 --hash=sha256:e3d36ff3653b50554d9ad2c95556224d1882a5db328eea8a9aa32a0eb08e4e80 --hash=sha256:e67e244ae4ca988b40783db7e1bac0de5b7f9f91062cdc0c93e219b189700388 --hash=sha256:eb0589fae351e123d8dbf0a8fbfd9e9cc033622b0e9f6e81684aa692be48688d --hash=sha256:ede6c56ae5d67bf068c4486f970f24b10b952d85dab0b44e7761749159a90d7f --hash=sha256:f797eada017668ca4c8c50664ff44437c461dc20233da0e12ff81327a13877fd --hash=sha256:f9271b4ff7430f63e6c20c28afacb75e97a384fafb336fe336985da80bcd8a49! Will try again.
  ================================ 65/65 - 00:02:12
Installing initially failed dependencies…
     ================================ 11/11 - 00:01:03
To activate this project's virtualenv, run pipenv shell.
Alternatively, run a command inside the virtualenv with pipenv run.
(python3.6) PS D:\github\django-tally> pipenv shell
Loading .env environment variables…
Launching subshell in virtual environment…
Windows PowerShell
Copyright (C) Microsoft Corporation. All rights reserved.

PS D:\github\django-tally> python manage.py runserver
Watching for file changes with StatReloader
Performing system checks...

C:\Users\guido\.virtualenvs\django-tally-QTYVOJb0\lib\site-packages\sklearn\utils\deprecation.py:144: FutureWarning: The sklearn.feature_extraction.stop_words module is  deprecated in version 0.22 and will be removed in version 0.24. The corresponding classes / functions should instead be imported from sklearn.feature_extraction.text. Anything that cannot be imported from sklearn.feature_extraction.text is now part of the private API.
  warnings.warn(message, FutureWarning)
System check identified no issues (0 silenced).
January 15, 2020 - 22:37:46
Django version 3.0.2, using settings 'tally.settings'
Starting development server at http://127.0.0.1:8000/
Quit the server with CTRL-BREAK.
[15/Jan/2020 22:41:21] "GET /yelp/jga_2HO_j4I7tSYf5cCEnQ?viztype=1 HTTP/1.1" 200 3110
[15/Jan/2020 22:41:29] "GET /yelp/jga_2HO_j4I7tSYf5cCEnQ?viztype=0 HTTP/1.1" 200 1535
[15/Jan/2020 22:41:38] "GET /yelp/jga_2HO_j4I7tSYf5cCEnQ?viztype=3 HTTP/1.1" 200 1535
[15/Jan/2020 22:41:46] "GET /yelp/jga_2HO_j4I7tSYf5cCEnQ?viztype=3 HTTP/1.1" 200 1535
[15/Jan/2020 22:41:49] "GET /yelp/jga_2HO_j4I7tSYf5cCEnQ?viztype=2 HTTP/1.1" 200 447
[15/Jan/2020 22:42:36] "GET /admin/ HTTP/1.1" 200 9997
[15/Jan/2020 22:42:39] "GET /admin/ HTTP/1.1" 200 9997
[15/Jan/2020 22:42:44] "GET /admin/djcelery/periodictask/ HTTP/1.1" 200 6084
[15/Jan/2020 22:42:45] "GET /admin/jsi18n/ HTTP/1.1" 200 3223
[15/Jan/2020 22:42:50] "GET /admin/djcelery/periodictask/1/change/ HTTP/1.1" 200 12033
[15/Jan/2020 22:42:51] "GET /admin/jsi18n/ HTTP/1.1" 200 3223
```